Workbook
Name AAA: #REF!
Name CLIENTES: 'Clientes por radial_V2'!$F:$F
Name CONSUMO: 'Clientes por radial_V2'!$F:$F
Name DATA: '[1]2022'!$C$9:$AE$104
Name ENERGIA_PLIEGO: 'Clientes por radial_V2'!#REF!
Name ENERGIA_PLIEGO: [2]SE!#REF!
Name Tasa: [3]PARAMETROS!$D$8
Name ValueSaveAsHTM: '[4]|PRIVATE|Template'!#REF!
Name XXX: #REF!

Sheet Informe
C2: ANALISIS DE CLIENTES MAYORES
B4: Cliente:
B5: Ubicación: | C5: Electro Dunas
B6: Solicitud: | C6: Factibilidad y Punto de Diseño | H6: —
B7: Potencia sol. (kW): | C7: 680 | G7: Fecha de Sol. de PyO: | H7: 46289
B8: Alimentador: | C8: CA101 | G8: SET: | H8: SET CA101
B9: Tension (kV): | C9: 10 | G9: Transformador: | H9: Transformador SET CA101 · 10.0 kV (inventario CYMDIST)
B10: Expediente: | C10: RECYM-CA101
B12: 1. ANTECEDENTES
B14: =CONCATENATE("El ",H7,", la Unidad de Proyectos y Obras distribución solicita evaluación de ",C6, " en media tensión, predio ubicado en el ",C5,".")
B15: =CONCATENATE("La solicitud esta registrado con ",C10)
B16: =CONCATENATE("El interesado solicita ",C6," ",H6,".")
B17: =CONCATENATE("El interesado se encuentra próximo al alimentador ",C8,".")
B18: =CONCATENATE("El transformador de la SET ",H8," tiene las siguientes características ",H9,".")
B20: 2. DESCRIPCIÓN
B22: Para realizar el análisis se ha considerado la información proporcionada por el interesado, reportes de mediciones de CCO e información del diagrama de Transmisión.
B26: 2.1 RED ACTUAL DE ELECTRODUNAS LL202
B28: A) TENSION
E30: Carga total
E31: kW | F31: kVAR | G31: kVA | H31: FP(%)
B32: Potencia desde las fuentes | E32: ='Resultados de escenarios'!H5 | F32: =+'Resultados de escenarios'!I5 | G32: =+'Resultados de escenarios'!G5 | H32: ='Resultados de escenarios'!R14
B33: Pérdidas | E33: ='Resultados de escenarios'!O28 | F33: ='Resultados de escenarios'!P28 | G33: ='Resultados de escenarios'!Q28 | H33: ='Resultados de escenarios'!R28
B36: Caida de Tension | C36: %
B37: A | C37: ='Resultados de escenarios'!L15
B38: B | C38: ='Resultados de escenarios'!L16
B39: C | C39: ='Resultados de escenarios'!L17
B67: B) CARGABILIDAD
B101: 2.1 RED PROYECTADA DE ELECTRODUNAS LL202
B103: A) TENSION
E105: Carga total
E106: kW | F106: kVAR | G106: kVA | H106: FP(%)
B107: Potencia desde las fuentes | E107: ='Resultados de escenarios'!O48 | F107: ='Resultados de escenarios'!P48 | G107: ='Resultados de escenarios'!Q48 | H107: ='Resultados de escenarios'!R48
B108: Pérdidas | E108: ='Resultados de escenarios'!O62 | F108: ='Resultados de escenarios'!P62 | G108: ='Resultados de escenarios'!Q62 | H108: ='Resultados de escenarios'!R62
B111: Caida de Tension | C111: %
B112: A | C112: ='Resultados de escenarios'!L49
B113: B | C113: ='Resultados de escenarios'!L50
B114: C | C114: ='Resultados de escenarios'!L51
B143: B) CARGABILIDAD
B174: C) ANALISIS DE PERDIDAS
B176: PORCENTAJES DE PÉRDIDAS POR SISTEMA ELÉCTRICO, RECONOCIDO POR OSINERGMIN
...

Sheet Evaluacion_LINEA DM CONTR.
A1: EVALUACIÓN DE SOLICITUD DE NUEVO SUMINISTRO
A2: =UPPER(Informe!C6)
A6: A) | B6: MAXIMA DEMANDA ACTUAL Y PROYECTADA:
B8: =UPPER(Informe!C4)
C10: =CONCATENATE("Máxima Demanda Actual ",Informe!C8, " :") | G10: =+CALCULOS_LINEA_OK!T6 | H10: kW
C11: =CONCATENATE("Máxima Demanda Proyectada ",Informe!C8, " :") | G11: =+CALCULOS_LINEA_OK!T12 | H11: kW
C12: Potencia Adicional Proyectada: | G12: =G11-G10 | H12: kW
A15: B) | B15: CAPACIDAD DISPONIBLE ACTUAL (Escenario en Mes de Alto Consumo) | K15: Tensión nominal (kV) | L15: 10
B17: ITEM | C17: ESCENARIO | D17: MAXIMA DEMANDA (kW) | E17: COSØ (%) | F17: MAXIMA DEMANDA (kVA) | G17: CAPACIDAD (kVA) * | H17: FACTOR DE UTILIZACION | I17: CAPACIDAD DISPONIBLE (kVA) | K17: EQUIPO | L17: CAPACIDAD (AMP.)
B18: =1 | C18: =CONCATENATE("CABLE DE SALIDA ",Informe!C8) | D18: =G10 | E18: =+'Resultados de escenarios'!R14 | F18: =+D18/E18*100 | G18: =$L$18*SQRT(3)*L15 | H18: =+F18/G18 | I18: =+G18-F18 | K18: CABLE SUBT. N2XSY - 120mm2 | L18: =1*331
B19: 2 | C19: =CONCATENATE("TRONCAL AÉREA ",Informe!C8) | D19: =D18 | E19: =+E21 | F19: =+D19/E19*100 | G19: =CALCULOS_LINEA_OK!Q6*SQRT(3)*L15 | H19: =+F19/G19 | I19: =+G19-F19 | K19: TC | L19: =400*1
B20: ITEM | C20: ESCENARIO | D20: MAXIMA DEMANDA (AMP) | E20: COSØ (%) | F20: MAXIMA DEMANDA (kVA) | G20: CAPACIDAD (AMP) * | H20: FACTOR DE UTILIZACION | I20: CAPACIDAD DISPONIBLE (AMP)
B21: 1 | C21: =CONCATENATE("TRAFO CTE ",Informe!C8) | D21: =CALCULOS_LINEA_OK!R6 | E21: =+E18 | F21: =F18 | G21: =L19 | H21: =+D21/G21 | I21: =+G21-D21
A23: C) | B23: CAPACIDAD DISPONIBLE PROYECTADA CON CARGA ADICIONAL DE PRISCO (900kW)
B25: ITEM | C25: ESCENARIO | D25: MAXIMA DEMANDA (kW) | E25: COSØ | F25: MAXIMA DEMANDA (kVA) | G25: CAPACIDAD (kVA) * | H25: FACTOR DE UTILIZACION | I25: CAPACIDAD DISPONIBLE (kVA)
B26: 1 | C26: TRAFO 01 (60kV) SET PARACAS | D26: =+#REF!+#REF! | E26: 0.97 | F26: =+D26/E26 | G26: 13000 | H26: =+F26/G26 | I26: =+G26-F26
B27: =1+B26 | C27: TRAFO 01 (10kV) SET PARACAS | D27: =+#REF!+#REF! | E27: 0.97 | F27: =+D27/E27 | G27: 9000 | H27: =+F27/G27 | I27: =+G27-F27
B28: =1+B27 | C28: TRAFO CTE. B10KV | D28: =+#REF!+#REF! | E28: 0.97 | F28: =+D28/E28 | G28: =500*1.732*10 | H28: =+F28/G28 | I28: =+G28-F28
B29: =1+B28 | C29: CABLE SALIDA PA08 | D29: =+D18+#REF! | E29: 0.97 | F29: =+D29/E29 | G29: =370*1.732*10 | H29: =+F29/G29 | I29: =+G29-F29
B30: =1+B29 | C30: TRAFO CTE. PA08 | D30: =+D21+#REF! | E30: =+E29 | F30: =+D30/E30 | G30: =300*1.732*10 | H30: =+F30/G30 | I30: =+G30-F30
B31: =1+B30 | C31: TRONCAL AÉREA PA08 | D31: =+D19+#REF! | E31: =+E30 | F31: =+D31/E31 | G31: =348*1.732*10 | H31: =+F31/G31 | I31: =+G31-F31
B32: (*) Capacidad ONAF en el caso de Transformador de Potencia.
A34: C) | B34: CAPACIDAD DISPONIBLE INCLUYENDO LAS CARGAS SOLICITADO Y OTRAS CARGAS
B36: ITEM | C36: ESCENARIO | D36: MAXIMA DEMANDA (kW) | E36: COSØ (%) | F36: MAXIMA DEMANDA (kVA) | G36: CAPACIDAD (kVA) * | H36: FACTOR DE UTILIZACION | I36: CAPACIDAD DISPONIBLE (kVA)
B37: =1 | C37: =CONCATENATE("CABLE DE SALIDA ",Informe!C8) | D37: =G11 | E37: =+'Resultados de escenarios'!R48 | F37: =+D37/E37*100 | G37: =L18*SQRT(3)*L15 | H37: =+F37/G37 | I37: =+G37-F37
B38: 2 | C38: =CONCATENATE("TRONCAL AÉREA ",Informe!C8) | D38: =D37 | E38: =+E37 | F38: =+D38/E38*100 | G38: =CALCULOS_LINEA_OK!Q12*SQRT(3)*L15 | H38: =+F38/G38 | I38: =+G38-F38
B39: ITEM | C39: ESCENARIO | D39: MAXIMA DEMANDA (AMP) | E39: COSØ (%) | F39: MAXIMA DEMANDA (kVA) | G39: CAPACIDAD (AMP) * | H39: FACTOR DE UTILIZACION | I39: CAPACIDAD DISPONIBLE (AMP)
B40: 1 | C40: =CONCATENATE("TRAFO CTE ",Informe!C8) | D40: =CALCULOS_LINEA_OK!R12 | E40: =+E37 | F40: =F37 | G40: =L19 | H40: =+D40/G40 | I40: =+G40-D40
A46: D) | B46: Resultados:
B48: - De acuerdo con el analisis realizado se aprecia que, con las demandas proyectadas el cable subterraneo, el transformador de corriente y la red aerea a la salida del SET tienen capacidad para atender las demandas a mediano plazo.

Sheet Resultados de escenarios
A2: ESCENARIO ACTUAL DEL ALIMENTADOR CA101
A3: 1 | B3: Estado actual.
B4: 𝑓𝑝é𝑟𝑑𝑖𝑑𝑎𝑠 = 0,3∗𝑓𝑐𝑎𝑟𝑔𝑎+0,7∗𝑓𝑐𝑎𝑟𝑔𝑎2 | C4: Vp.u. | D4: kVLL | E4: kVLN | F4: i (A) | G4: KVA | H4: kW | I4: kVAR
C5: 0.802 | D5: 10 | E5: 5.8 | F5: 175.3 | G5: 3036.95 | H5: 3022 | I5: 301
B6: FC | C6: 0.74
B7: Fperdida | C7: =0.7*C6*C6+0.3*C6
B10: Costo anual de las pérdidas del sistema | H10: Condiciones anormales | N10: Flujo de carga - Reporte sumario
C11: kW | D11: MW-h/año | E11: k$/año | I11: Fase | J11: Conteo | K11: Peor caso | L11: Valor | N11: Resumen total | O11: kW | P11: kvar | Q11: kVA | R11: FP(%)
B12: Pérdidas en las líneas | H12: Sobrecarga | I12: A | J12: 0 | N12: Fuentes (Potencia de equilibrio) | O12: 3022 | P12: 301 | Q12: 3036.95 | R12: 99.51
B13: Pérdidas en los cables | C13: 0 | D13: 0 | E13: 0 | I13: B | J13: 0 | N13: Generadores | O13: 0 | P13: 0 | Q13: 0 | R13: 0
B14: Pérdidas de carga del transformador | C14: 0 | D14: 0 | E14: 0 | I14: C | J14: 0 | N14: Producción total | O14: 3022 | P14: 301 | Q14: 3036.95 | R14: 99.51
B15: Pérdidas en vacío del transformador | C15: 0 | D15: 0 | E15: 0 | H15: Subtensión | I15: A | J15: 0 | L15: 0.802 | N15: Carga leída (no regulada) | O15: 3022 | P15: 301 | Q15: 3036.95 | R15: 99.51
B16: Pérdidas totales | I16: B | J16: 0 | L16: 0.802 | N16: Carga utilizada (regulada) | O16: 3022 | P16: 301 | Q16: 3036.95 | R16: 99.51
I17: C | J17: 0 | L17: 0.802 | N17: Condensadores shunt (regulados) | O17: 0 | P17: 0 | Q17: 0 | R17: 0
B18: Dato del registro de mediciones | H18: Sobretensión | I18: A | J18: 0 | N18: Reactancias shunt(reguladas) | O18: 0 | P18: 0 | Q18: 0 | R18: 0
B19: Energia kwh/año | I19: B | J19: 0 | N19: Motores | O19: 0 | P19: 0 | Q19: 0 | R19: 0
B20: Energia MW-h/año | I20: C | J20: 0 | N20: Cargas totales | O20: 3022 | P20: 301 | Q20: 3036.95 | R20: 99.51
N21: Capacitancia del cable
N22: Capacitancia de la línea
N23: Capacitancia shunt total
N24: Pérdidas en las líneas
N25: Pérdidas en los cables
N26: Pérdidas de carga del transformador
N27: Pérdidas en vacío del transformador
N28: Pérdidas totales
B34: ESCENARIO PROYECTADO DEL ALIMENTADOR A LL202
A37: 1 | B37: Estado proyectado_parte 1
B38: 𝑓𝑝é𝑟𝑑𝑖𝑑𝑎𝑠 = 0,3∗𝑓𝑐𝑎𝑟𝑔𝑎+0,7∗𝑓𝑐𝑎𝑟𝑔𝑎2 | C38: Vp.u. | D38: kVLL | E38: kVLN | F38: i (A) | G38: KVA | H38: kW | I38: kVAR
C39: 0.99 | D39: 9.9 | E39: 5.7 | F39: 199 | G39: 3233.12 | H39: 3233.12 | I39: 1156.66
B40: FC | C40: 0.74
B41: Fperdida | C41: =0.7*C40*C40+0.3*C40
B44: Costo anual de las pérdidas del sistema | H44: Condiciones anormales | N44: Flujo de carga - Reporte sumario
C45: kW | D45: MW-h/año | E45: k$/año | I45: Fase | J45: Conteo | K45: Peor caso | L45: Valor | N45: Resumen total | O45: kW | P45: kvar | Q45: kVA | R45: FP(%)
B46: Pérdidas en las líneas | C46: 157.61 | D46: 505.5 | E46: 50.55 | H46: Sobrecarga | I46: A | J46: 2 | K46: SEC_2010_329525_SE70004 | L46: 1.7367 | N46: Fuentes (Potencia de equilibrio) | O46: 3233.12 | P46: 1156.66 | Q46: 3433.79 | R46: 94.16
B47: Pérdidas en los cables | C47: 0 | D47: 0 | E47: 0 | I47: B | J47: 1 | K47: SEC_2010_329525_SE70004 | L47: 1.7366 | N47: Generadores | O47: 0 | P47: 0 | Q47: 0 | R47: 0
B48: Pérdidas de carga del transformador | C48: 0 | D48: 0 | E48: 0 | I48: C | J48: 1 | K48: SEC_2010_329525_SE70004 | L48: 1.7368 | N48: Producción total | O48: 3233.12 | P48: 1156.66 | Q48: 3433.79 | R48: 94.16
B49: Pérdidas en vacío del transformador | C49: 0 | D49: 0 | E49: 0 | H49: Subtensión | I49: A | J49: 0 | K49: 37 | L49: 0.9652 | N49: Carga leída (no regulada) | O49: 3182.04 | P49: 1101.44 | Q49: 3367.28 | R49: 94.5
B50: Pérdidas totales | C50: 157.61 | D50: 505.5 | E50: 50.55 | I50: B | J50: 0 | K50: 37 | L50: 0.9599 | N50: Carga utilizada (regulada) | O50: 3182 | P50: 1101.38 | Q50: 3367.22 | R50: 94.5
I51: C | J51: 0 | K51: 37 | L51: 0.9643 | N51: Condensadores shunt (regulados) | O51: 0 | P51: 0 | Q51: 0 | R51: 0
B52: Dato del registro de mediciones | H52: Sobretensión | I52: A | J52: 0 | K52: NET_2030_147_LL202 | L52: 1.0483 | N52: Reactancias shunt(reguladas) | O52: 0 | P52: 0 | Q52: 0 | R52: 0
...

Sheet CALCULOS_LINEA_OK
D2: =CONCATENATE("CALCULO DE CARGAS, PERDIDAS Y VARIACION DE TENSION EN ",Informe!C8) | Q2: TENSION DE DESPACHO KV | R2: ='Resultados de escenarios'!D5
E4: CARGA DE LINEA AEREA | F4: PERDIDAS (KW) | G4: PERDIDAS (%) | H4: CAIDA DE TENSION | I4: COMENTARIOS | P4: CAPACIDAD DISPONIBLE EN LINEA | Q4: CAPACIDAD DE LINEA (A) AEREA | R4: CORRIENTE ACT. (A) | T4: POTENCIA ACTUAL kW
D6: =CONCATENATE("ESTADO ACTUAL - ",Informe!C8) | E6: =+R6/Q6 | F6: =+'Resultados de escenarios'!O28 | G6: =+F6/T6 | H6: =1-(MIN(Informe!C37:C39)) | I6: Condición actual. | M6: =340*2 | P6: =+Q6-R6 | Q6: 240 | R6: ='Resultados de escenarios'!F5 | T6: 270
B10: ESCENARIO PROYECTADO : | E10: CARGA DE LINEA AEREA | F10: PERDIDAS (KW) | G10: PERDIDAS (%) | H10: CAIDA DE TENSION | I10: COMENTARIOS | K10: INCREMENTO DE PERDIDAS EN TA123 POR CONEXIÓN DE CARGA SOLICITADA | M10: PERDIDAS RESPECTO A LA DEMANDA SOL. (%) | P10: CAPACIDAD DISPONIBLE EN LINEA | Q10: CAPACIDAD DE LINEA (A) AEREA | R10: CORRIENTE PROY (A) | T10: POTENCIA PROY kW
B11: Demanda solicitada (KW) | K11: (KW) | L11: (%)
B12: =+T12-T6 | D12: =CONCATENATE("ESTADO CON CARGA PROYECTADA - ",Informe!C8) | E12: =+R12/Q12 | F12: =+'Resultados de escenarios'!O62 | G12: =+F12/T12 | H12: =1-(MIN(Informe!C112:C114)) | I12: Situción con demanda proyectada. | K12: =+F12-$F$6 | L12: =+K12/F12 | M12: =+K12/B12 | P12: =+Q12-R12 | Q12: 240 | R12: ='Resultados de escenarios'!F39 | T12: 318.78

Sheet Clientes por radial_V2
D2: SISTEMAS ELECTRICOS ELECTRODUNAS
D4: Codigo Sist. Elect. | E4: Nombre Sist. Elect. | F4: Sector Tipico Resol 205-2018 OSINERG | G4: Codigo SET | H4: Codigo VNR Alimentador | I4: OBSERVACION
J5: 22/01/2019_IGEA | K5: 26/04/2019_IGEA | L5: 11/07/2019_VNR | M5: 04/02/2020_VNR | N5: 28/02/2020_VNR & IGEA | O5: 21/05/2020_SGN | P5: Junio/2020_SGN | Q5: 24/11/2020_VNR | R5: 08/03/2021_IGEA | S5: 07/10/2021_VNR | T5: 28/02/2022_VNR | U5: 16/08/2022_VNR | V5: 03/01/2023_VNR
B6: CHINCHA | C6: CA101 | D6: SE1043 | E6: Chincha Baja Densidad | F6: 2 | G6: SET 21 EL CARMEN | H6: CA101 | I6: EN SERVICIO | J6: 3087 | K6: 3108 | L6: 3092 | M6: 3138 | N6: 3145 | O6: 3129 | P6: 3138 | Q6: 3176 | R6: 3204 | S6: 3246 | T6: 3260 | U6: 3275 | V6: 3268
C7: CA103 | D7: SE1043 | E7: Chincha Baja Densidad | F7: 2 | H7: CA103 | I7: FUERA DE SERVICIO
C8: CA104 | D8: SE1043 | E8: Chincha Baja Densidad | F8: 2 | H8: CA104 | I8: EN SERVICIO | J8: 37 | K8: 37 | L8: 37 | M8: 35 | N8: 35 | O8: 35 | P8: 35 | Q8: 34 | R8: 34 | S8: 34 | T8: 34 | U8: 34 | V8: 34
C9: CA105 | D9: SE1043 | E9: Chincha Baja Densidad | F9: 2 | H9: CA105 | I9: EN SERVICIO | J9: 516 | K9: 518 | L9: 515 | M9: 511 | N9: 511 | O9: 510 | P9: 510 | Q9: 512 | R9: 514 | S9: 519 | T9: 524 | U9: 485 | V9: 476
C10: CA206 | D10: SE1043 | E10: Chincha Baja Densidad | F10: 2 | H10: CA206 | I10: EN SERVICIO | J10: 516 | K10: 518 | L10: 515 | M10: 511 | N10: 511 | O10: 510 | U10: 38 | V10: 39
C11: TM101 | D11: SE1043 | E11: Chincha Baja Densidad | F11: 2 | G11: SET 22 TAMBO DE MORA | H11: TM101 | I11: FUERA DE SERVICIO
C12: TM102 | D12: SE1043 | E12: Chincha Baja Densidad | F12: 2 | H12: TM102 | I12: EN SERVICIO | J12: 326 | K12: 327 | L12: 324 | M12: 325 | N12: 325 | O12: 324 | P12: 324 | Q12: 331 | R12: 330 | S12: 327 | T12: 329 | U12: 331 | V12: 319
C13: TM103 | D13: SE1043 | E13: Chincha Baja Densidad | F13: 2 | H13: TM103 | I13: EN SERVICIO | J13: 2 | K13: 2 | L13: 2 | M13: 2 | N13: 2 | O13: 2 | P13: 2 | Q13: 2 | R13: 2 | S13: 2 | T13: 2 | U13: 2 | V13: 2
C14: TM104 | D14: SE1043 | E14: Chincha Baja Densidad | F14: 2 | H14: TM104 | I14: EN SERVICIO | J14: 1517 | K14: 1527 | L14: 239 | M14: 1891 | N14: 1896 | O14: 1894 | P14: 1897 | Q14: 1940 | R14: 1968 | S14: 1980 | T14: 1990 | U14: 1998 | V14: 1998
C15: TM105 | D15: SE1043 | E15: Chincha Baja Densidad | F15: 2 | H15: TM105 | I15: EN SERVICIO | J15: 3337 | K15: 3362 | L15: 45 | M15: 3427 | N15: 47 | O15: 47 | P15: 47 | Q15: 3542 | R15: 3608 | S15: 3696 | T15: 3724 | U15: 3795 | V15: 51
C16: TM106 | D16: SE1043 | E16: Chincha Baja Densidad | F16: 2 | H16: TM106 | I16: EN SERVICIO
C17: PN101 | D17: SE0043 | E17: Chincha | F17: 2 | G17: SET 23 PUEBLO NUEVO | H17: PN101 | I17: EN SERVICIO | J17: 4255 | K17: 4314 | L17: 4304 | M17: 4317 | N17: 4327 | O17: 4333 | P17: 4324 | Q17: 4349 | R17: 4339 | S17: 4486 | T17: 4490 | U17: 4470 | V17: 4899
C18: PN102 | D18: SE0043 | E18: Chincha | F18: 2 | H18: PN102 | I18: EN SERVICIO | J18: 3550 | K18: 3569 | L18: 3565 | M18: 3579 | N18: 3585 | O18: 3594 | P18: 3602 | Q18: 3643 | R18: 3664 | S18: 3543 | T18: 3557 | U18: 3556 | V18: 3567
C19: PN103 | D19: SE0043 | E19: Chincha | F19: 2 | H19: PN103 | I19: EN SERVICIO | J19: 7754 | K19: 7810 | L19: 7815 | M19: 7874 | N19: 7905 | O19: 7923 | P19: 7942 | Q19: 8053 | R19: 8132 | S19: 8224 | T19: 8270 | U19: 8279 | V19: 8286
C20: PN104 | D20: SE0043 | E20: Chincha | F20: 2 | H20: PN104 | I20: EN SERVICIO
C21: PN105 | D21: SE0043 | E21: Chincha | F21: 2 | H21: PN105 | I21: EN SERVICIO | J21: 303 | K21: 303 | L21: 302 | M21: 304 | N21: 305 | O21: 309 | P21: 311 | Q21: 312 | R21: 328
C22: PN106 | D22: SE0043 | E22: Chincha | F22: 2 | H22: PN106 | I22: EN SERVICIO | J22: 7525 | K22: 7549 | L22: 10862 | M22: 7573 | N22: 10997 | O22: 11032 | P22: 11084 | Q22: 7816 | R22: 7865 | S22: 7981 | T22: 8021 | U22: 8063 | V22: 11430
C23: PN107 | D23: SE0043 | E23: Chincha | F23: 2 | H23: PN107 | I23: EN SERVICIO | J23: 9922 | K23: 9989 | L23: 9980 | M23: 10058 | N23: 10087 | O23: 10091 | P23: 10123 | Q23: 10268 | R23: 10399 | S23: 10522 | T23: 10580 | U23: 10622 | V23: 10665
C24: PN208 | D24: SE0043 | E24: Chincha | F24: 2 | H24: PN208 | I24: EN SERVICIO | J24: 1807 | K24: 1837 | L24: 1821 | M24: 1853 | N24: 1870 | O24: 1876 | P24: 1883 | Q24: 1915 | R24: 1949 | S24: 1979 | T24: 2003 | V24: 1981
C25: PN209 | D25: SE0043 | E25: Chincha | F25: 2 | H25: PN209 | I25: EN SERVICIO | S25: 351 | T25: 355 | U25: 2335 | V25: 351
C26: PE101 | D26: SE1043 | E26: Chincha Baja Densidad | F26: 2 | G26: SET 25 PEDREGAL | H26: PE101 | I26: EN SERVICIO | J26: 1921 | K26: 1940 | L26: 1934 | M26: 1648 | N26: 1649 | O26: 1646 | P26: 1655 | Q26: 1673 | R26: 1698 | S26: 1715 | T26: 1731 | U26: 1729 | V26: 1732
C27: PE102 | D27: SE1043 | E27: Chincha Baja Densidad | F27: 2 | H27: PE102 | I27: EN SERVICIO | J27: 1286 | K27: 1288 | L27: 2583 | M27: 1206 | N27: 1210 | O27: 1213 | P27: 1221 | Q27: 1240 | R27: 1251 | S27: 1259 | T27: 1265 | U27: 1279 | V27: 1279
C28: PE103 | D28: SE0043 | E28: Chincha | F28: 2 | H28: PE103 | I28: EN SERVICIO | J28: 6174 | K28: 6204 | L28: 6159 | M28: 6207 | N28: 6225 | O28: 6239 | P28: 6277 | Q28: 6422 | R28: 6475 | S28: 6583 | T28: 6625 | U28: 6760 | V28: 6818
C29: PE104 | D29: SE0043 | E29: Chincha | F29: 2 | H29: PE104 | I29: EN SERVICIO | J29: 1418 | K29: 1423 | L29: 1454 | M29: 1489 | N29: 1497 | O29: 1502 | P29: 1509 | Q29: 1538 | R29: 1560 | S29: 1588 | T29: 1617 | U29: 1630 | V29: 1629
C30: PE105 | D30: SE0043 | E30: Chincha | F30: 2 | H30: PE105 | I30: EN SERVICIO | J30: 1429 | K30: 1428 | L30: 1431 | M30: 1471 | N30: 1472 | O30: 1476 | P30: 1484 | Q30: 1512 | R30: 1515 | S30: 1527 | T30: 1541 | U30: 1547 | V30: 1557
C31: PE106 | D31: SE1043 | E31: Chincha Baja Densidad | F31: 2 | H31: PE106 | I31: EN SERVICIO | S31: 1 | T31: 1 | U31: 1 | V31: 1
B32: PISCO | C32: PI101 | D32: SE0046 | E32: PISCO | F32: 2 | G32: SET 31 PISCO | H32: PI101 | I32: FUERA DE SERVICIO
C33: PI102 | D33: SE0046 | E33: PISCO | F33: 2 | H33: PI102 | I33: EN SERVICIO | J33: 2998 | K33: 2983 | L33: 2956 | M33: 2995 | N33: 2998 | O33: 2999 | P33: 3014 | Q33: 3038 | R33: 3035 | S33: 3066 | T33: =VLOOKUP(H33,[5]Hoja3!$E$4:$F$84,2,0) | U33: 2752 | V33: 2761
C34: PI103 | D34: SE0046 | E34: PISCO | F34: 2 | H34: PI103 | I34: EN SERVICIO | J34: 4037 | K34: 4025 | L34: 3978 | M34: 4029 | N34: 4033 | O34: 4015 | P34: 4466 | Q34: 4498 | R34: 4500 | S34: 4667 | T34: =VLOOKUP(H34,[5]Hoja3!$E$4:$F$84,2,0) | U34: 4699 | V34: 4685
C35: PI116 | D35: SE0046 | E35: PISCO | F35: 2 | H35: PI116 | I35: EN SERVICIO | J35: 1739 | K35: 1861 | L35: 1846 | M35: 1870 | N35: 1872 | O35: 1877 | P35: 1880 | Q35: 1889 | R35: 1887 | S35: 1920 | T35: =VLOOKUP(H35,[5]Hoja3!$E$4:$F$84,2,0) | U35: 1933 | V35: 1940
C36: AL104 | D36: SE0046 | E36: PISCO | F36: 2 | G36: SET 33 ALTO LA LUNA | H36: AL104 | I36: EN SERVICIO | J36: 899 | K36: 904 | L36: 901 | M36: 921 | N36: 924 | O36: 927 | P36: 934 | Q36: 1015 | R36: 1108 | S36: 1194 | T36: =VLOOKUP(H36,[5]Hoja3!$E$4:$F$84,2,0) | U36: 1683 | V36: 1728
C37: AL105 | D37: SE0046 | E37: PISCO | F37: 2 | H37: AL105 | I37: EN SERVICIO | J37: 8148 | K37: 8172 | L37: 8064 | M37: 8222 | N37: 8238 | O37: 8227 | P37: 8265 | Q37: 8372 | R37: 8417 | S37: 8485 | T37: =VLOOKUP(H37,[5]Hoja3!$E$4:$F$84,2,0) | U37: 8474 | V37: 8477
C38: AL106 | D38: SE0046 | E38: PISCO | F38: 2 | H38: AL106 | I38: EN SERVICIO | J38: 7621 | K38: 7635 | L38: 7590 | M38: 7650 | N38: 7663 | O38: 7644 | P38: 7230 | Q38: 7282 | R38: 7275 | S38: 7094 | T38: =VLOOKUP(H38,[5]Hoja3!$E$4:$F$84,2,0) | U38: 7044 | V38: 7038
C39: AL107 | D39: SE0046 | E39: PISCO | F39: 2 | H39: AL107 | I39: FUERA DE SERVICIO
C40: AL108 | D40: SE0046 | E40: PISCO | F40: 2 | H40: AL108 | I40: EN SERVICIO | J40: 6151 | K40: 6163 | L40: 6061 | M40: 6169 | N40: 6188 | O40: 6196 | P40: 6219 | Q40: 6329 | R40: 6387 | S40: 6399 | T40: =VLOOKUP(H40,[5]Hoja3!$E$4:$F$84,2,0) | U40: 6370 | V40: 6347
C41: AL209 | D41: SE0046 | E41: PISCO | F41: 2 | H41: AL209 | I41: EN SERVICIO | J41: 1 | K41: 1 | L41: 1 | U41: 2 | V41: 3
C42: PA108 | D42: SE2046 | E42: PARACAS | F42: 2 | G42: SET 32 PARACAS | H42: PA108 | I42: EN SERVICIO | J42: 14 | K42: 14 | L42: 14 | M42: 13 | N42: 13 | O42: 13 | P42: 13 | Q42: 13 | R42: 13 | S42: 13 | T42: =VLOOKUP(H42,[5]Hoja3!$E$4:$F$84,2,0) | U42: 14 | V42: 14
...

Sheet Perdidas_ELDU
G1: 29 | H1: 29 | I1: 41 | J1: 41 | K1: 42 | L1: 42 | M1: 27 | N1: 27 | O1: 28 | P1: 28 | Q1: 29 | R1: 29 | S1: 30 | T1: 30 | W1: 58 | X1: 58
C2: PORCENTAJES DE PÉRDIDAS POR SISTEMA ELÉCTRICO, SECTOR TÍPICO Y EMPRESA - ELECTRO DUNAS S.A.A.
C4: Ítem | D4: Código | E4: Sector Típico | F4: Sistema Eléctrico | G4: Pérdidas Técnicas en MT (%) | I4: Pérdidas Técnicas en BT (%) | K4: Pérdidas No Técnicas en BT (%) | M4: Pérdidas en Subestaciones MT/BT (%) | O4: Pérdidas en Redes de BT (%) | Q4: Pérdidas en Acometidas (%) | S4: Pérdidas en Medidores (%) | U4: Pérdidas Totales en BT (%) | W4: Total Pérdidas Respecto MT (%) | Z4: Pérdidas en Subestaciones MT/BT Adapatada (%) | AB4: Pérdidas Medición Centralizada (%)
G5: Energía | H5: Potencia | I5: Energía | J5: Potencia | K5: Energía | L5: Potencia | M5: Energía | N5: Potencia | O5: Energía | P5: Potencia | Q5: Energía | R5: Potencia | S5: Energía | T5: Potencia | U5: Energía | V5: Potencia | W5: Energía | X5: Potencia | Z5: Energía | AA5: Potencia | AB5: Energía | AC5: Potencia
B6: Empresa | C6: 1 | D6: Emp | E6: Emp | F6: Empresa | G6: 1.15 | H6: 1.77 | I6: 5.66 | J6: 7.78 | K6: 2.56 | L6: 2.56 | M6: 2.25 | N6: 3.14 | O6: 3.22 | P6: 4.39 | Q6: 0.05 | R6: 0.07 | S6: 0.14 | T6: 0.19 | U6: 8.22 | V6: 10.35 | W6: 4.51 | X6: 6.73 | Z6: 5 | AA6: 5.96 | AB6: 8.03 | AC6: 10.09
B7: Sector_Típico_2 | C7: 2 | D7: ST2 | E7: ST2 | F7: Sector_Típico_2 | G7: 0.68 | H7: 1.04 | I7: 5.84 | J7: 7.99 | K7: 2.56 | L7: 2.56 | M7: 2.27 | N7: 3.1 | O7: 3.39 | P7: 4.63 | Q7: 0.05 | R7: 0.07 | S7: 0.13 | T7: 0.18 | U7: 8.4 | V7: 10.54 | W7: 4.3 | X7: 6.26 | Z7: 5.01 | AA7: 5.91 | AB7: 8.22 | AC7: 10.29
B8: Sector_Típico_3 | C8: 3 | D8: ST3 | E8: ST3 | F8: Sector_Típico_3 | G8: 4.02 | H8: 6.03 | I8: 3.74 | J8: 5.7 | K8: 2.56 | L8: 2.56 | M8: 2.05 | N8: 3.17 | O8: 1.5 | P8: 2.23 | Q8: 0.03 | R8: 0.05 | S8: 0.16 | T8: 0.25 | U8: 6.3 | V8: 8.26 | W8: 5.39 | X8: 8.72 | Z8: 4.8 | AA8: 6.03 | AB8: 6.11 | AC8: 7.96
B9: Sector_Típico_4 | C9: 4 | D9: ST4 | E9: ST4 | F9: Sector_Típico_4 | G9: 5.74 | H9: 8.94 | I9: 4.41 | J9: 7.3 | K9: 2.56 | L9: 2.56 | M9: 2.26 | N9: 3.83 | O9: 1.81 | P9: 2.88 | Q9: 0.03 | R9: 0.05 | S9: 0.31 | T9: 0.53 | U9: 6.97 | V9: 9.85 | W9: 10.55 | X9: 16.07 | Z9: 5.16 | AA9: 6.97 | AB9: 6.63 | AC9: 9.27
B10: Sector_Típico_SER | C10: 5 | D10: SER | E10: SER | F10: Sector_Típico_SER | G10: 1.86 | H10: 3.32 | I10: 4.5 | J10: 7.82 | K10: 2.56 | L10: 2.56 | M10: 2.33 | N10: 4.05 | O10: 2.17 | P10: 3.77 | Q10: 0 | R10: 0 | S10: 0 | T10: 0 | U10: 7.06 | V10: 10.38 | W10: 8.79 | X10: 13.35 | Z10: 4.89 | AA10: 6.61 | AB10: 7.06 | AC10: 10.38
B11: Chincha | C11: 6 | D11: SE0043 | E11: ST2 | F11: Chincha | G11: 0.8 | H11: 1.2 | I11: 6.25 | J11: 8.32 | K11: 2.56 | L11: 2.56 | M11: 2.33 | N11: 3.11 | O11: 3.71 | P11: 4.95 | Q11: 0.05 | R11: 0.07 | S11: 0.15 | T11: 0.2 | U11: 8.8 | V11: 10.89 | W11: 5.89 | X11: 8.87 | Z11: 5.09 | AA11: 5.94 | AB11: 8.6 | AC11: 10.62
B12: Ica | C12: 7 | D12: SE0044 | E12: ST2 | F12: Ica | G12: 0.79 | H12: 1.2 | I12: 5.97 | J12: 8.13 | K12: 2.56 | L12: 2.56 | M12: 2.34 | N12: 3.19 | O12: 3.45 | P12: 4.7 | Q12: 0.05 | R12: 0.07 | S12: 0.12 | T12: 0.17 | U12: 8.52 | V12: 10.69 | W12: 6.03 | X12: 8.28 | Z12: 5.07 | AA12: 5.99 | AB12: 8.35 | AC12: 10.45
B13: Pisco | C13: 8 | D13: SE0046 | E13: ST2 | F13: Pisco | G13: 0.7 | H13: 1.03 | I13: 5.82 | J13: 8.08 | K13: 2.56 | L13: 2.56 | M13: 2.22 | N13: 3.08 | O13: 3.41 | P13: 4.73 | Q13: 0.05 | R13: 0.07 | S13: 0.13 | T13: 0.19 | U13: 8.37 | V13: 10.63 | W13: 5.54 | X13: 8.05 | Z13: 4.96 | AA13: 5.9 | AB13: 8.19 | AC13: 10.37
B14: Nasca | C14: 9 | D14: SE1045 | E14: ST2 | F14: Nasca | G14: 0.66 | H14: 0.88 | I14: 5.28 | J14: 7.51 | K14: 2.56 | L14: 2.56 | M14: 2.06 | N14: 2.93 | O14: 3.06 | P14: 4.36 | Q14: 0.04 | R14: 0.06 | S14: 0.11 | T14: 0.16 | U14: 7.83 | V14: 10.07 | W14: 6.13 | X14: 8.86 | Z14: 4.77 | AA14: 5.71 | AB14: 7.68 | AC14: 9.85
B15: Paracas | C15: 10 | D15: SE2046 | E15: ST2 | F15: Paracas | G15: 0.56 | H15: 0.87 | I15: 5.07 | J15: 7.28 | K15: 2.56 | L15: 2.56 | M15: 2.11 | N15: 3.03 | O15: 2.82 | P15: 4.05 | Q15: 0.06 | R15: 0.08 | S15: 0.08 | T15: 0.12 | U15: 7.63 | V15: 9.84 | W15: 1.49 | X15: 1.79 | Z15: 4.81 | AA15: 5.79 | AB15: 7.49 | AC15: 9.64
B16: Santa_Margarita | C16: 11 | D16: SE2044 | E16: ST2 | F16: Santa_Margarita | G16: 0.3 | H16: 0.55 | I16: 4.49 | J16: 6.22 | K16: 2.56 | L16: 2.56 | M16: 1.94 | N16: 2.69 | O16: 2.33 | P16: 3.23 | Q16: 0.05 | R16: 0.07 | S16: 0.17 | T16: 0.24 | U16: 7.05 | V16: 8.79 | W16: 1.69 | X16: 2.75 | Z16: 4.72 | AA16: 5.56 | AB16: 6.83 | AC16: 8.48
B17: Chincha_Baja_Densidad | C17: 12 | D17: SE1043 | E17: ST2 | F17: Chincha_Baja_Densidad | G17: 0.74 | H17: 1.17 | I17: 5.87 | J17: 8.55 | K17: 2.56 | L17: 2.56 | M17: 2.27 | N17: 3.3 | O17: 3.47 | P17: 5.05 | Q17: 0.03 | R17: 0.04 | S17: 0.11 | T17: 0.17 | U17: 8.44 | V17: 11.12 | W17: 1.64 | X17: 2.94 | Z17: 4.97 | AA17: 6.07 | AB17: 8.3 | AC17: 10.91
... B32: SER_Nasca | C32: 27 | D32: SR0045 | E32: SER | F32: SER_Nasca | G32: 1.8 | H32: 3.32 | I32: 4.34 | J32: 7.82 | K32: 2.56 | L32: 2.56 | M32: 2.25 | N32: 4.05 | O32: 2.09 | P32: 3.77 | Q32: 0 | R32: 0 | S32: 0 | T32: 0 | U32: 6.9 | V32: 10.38 | W32: 8.58 | X32: 13.35 | Z32: 4.81 | AA32: 6.61 | AB32: 6.9 | AC32: 10.38
C35: FACTOR DE EXPANSIÓN DE PERDIDAS DE ELECTRO DUNAS S.A.A.
C37: Ítem | D37: Código | E37: Sector Típico | F37: Sistema Eléctrico | G37: PEMT | H37: PPMT | I37: PEBTSED | J37: PPBTSED | K37: PEBT | L37: PPBT | M37: PEBTCO | N37: PPBTCO
C39: 1 | D39: Emp | E39: Emp | F39: Empresa | G39: =ROUND(1/(1-G6/100),4) | H39: =ROUND(1/(1-H6/100),4) | I39: =ROUND(1/(1-(U6-O6-Q6-S6)/100),4) | J39: =ROUND(1/(1-(V6-P6-R6-T6)/100),4) | K39: =ROUND(1/(1-U6/100),4) | L39: =ROUND(1/(1-V6/100),4) | M39: =ROUND(1/(1-AB6/100),4) | N39: =ROUND(1/(1-AC6/100),4)
C40: 2 | D40: ST2 | E40: ST2 | F40: Sector_Típico_2 | G40: =ROUND(1/(1-G7/100),4) | H40: =ROUND(1/(1-H7/100),4) | I40: =ROUND(1/(1-(U7-O7-Q7-S7)/100),4) | J40: =ROUND(1/(1-(V7-P7-R7-T7)/100),4) | K40: =ROUND(1/(1-U7/100),4) | L40: =ROUND(1/(1-V7/100),4) | M40: =ROUND(1/(1-AB7/100),4) | N40: =ROUND(1/(1-AC7/100),4)
C41: 3 | D41: ST3 | E41: ST3 | F41: Sector_Típico_3 | G41: =ROUND(1/(1-G8/100),4) | H41: =ROUND(1/(1-H8/100),4) | I41: =ROUND(1/(1-(U8-O8-Q8-S8)/100),4) | J41: =ROUND(1/(1-(V8-P8-R8-T8)/100),4) | K41: =ROUND(1/(1-U8/100),4) | L41: =ROUND(1/(1-V8/100),4) | M41: =ROUND(1/(1-AB8/100),4) | N41: =ROUND(1/(1-AC8/100),4)
C42: 4 | D42: ST4 | E42: ST4 | F42: Sector_Típico_4 | G42: =ROUND(1/(1-G9/100),4) | H42: =ROUND(1/(1-H9/100),4) | I42: =ROUND(1/(1-(U9-O9-Q9-S9)/100),4) | J42: =ROUND(1/(1-(V9-P9-R9-T9)/100),4) | K42: =ROUND(1/(1-U9/100),4) | L42: =ROUND(1/(1-V9/100),4) | M42: =ROUND(1/(1-AB9/100),4) | N42: =ROUND(1/(1-AC9/100),4)
C43: 5 | D43: SER | E43: SER | F43: Sector_Típico_SER | G43: =ROUND(1/(1-G10/100),4) | H43: =ROUND(1/(1-H10/100),4) | I43: =ROUND(1/(1-(U10-O10-Q10-S10)/100),4) | J43: =ROUND(1/(1-(V10-P10-R10-T10)/100),4) | K43: =ROUND(1/(1-U10/100),4) | L43: =ROUND(1/(1-V10/100),4) | M43: =ROUND(1/(1-AB10/100),4) | N43: =ROUND(1/(1-AC10/100),4)
C44: 6 | D44: SE0043 | E44: ST2 | F44: Chincha | G44: =ROUND(1/(1-G11/100),4) | H44: =ROUND(1/(1-H11/100),4) | I44: =ROUND(1/(1-(U11-O11-Q11-S11)/100),4) | J44: =ROUND(1/(1-(V11-P11-R11-T11)/100),4) | K44: =ROUND(1/(1-U11/100),4) | L44: =ROUND(1/(1-V11/100),4) | M44: =ROUND(1/(1-AB11/100),4) | N44: =ROUND(1/(1-AC11/100),4)
C45: 7 | D45: SE0044 | E45: ST2 | F45: Ica | G45: =ROUND(1/(1-G12/100),4) | H45: =ROUND(1/(1-H12/100),4) | I45: =ROUND(1/(1-(U12-O12-Q12-S12)/100),4) | J45: =ROUND(1/(1-(V12-P12-R12-T12)/100),4) | K45: =ROUND(1/(1-U12/100),4) | L45: =ROUND(1/(1-V12/100),4) | M45: =ROUND(1/(1-AB12/100),4) | N45: =ROUND(1/(1-AC12/100),4)
C46: 8 | D46: SE0046 | E46: ST2 | F46: Pisco | G46: =ROUND(1/(1-G13/100),4) | H46: =ROUND(1/(1-H13/100),4) | I46: =ROUND(1/(1-(U13-O13-Q13-S13)/100),4) | J46: =ROUND(1/(1-(V13-P13-R13-T13)/100),4) | K46: =ROUND(1/(1-U13/100),4) | L46: =ROUND(1/(1-V13/100),4) | M46: =ROUND(1/(1-AB13/100),4) | N46: =ROUND(1/(1-AC13/100),4)
C47: 9 | D47: SE1045 | E47: ST2 | F47: Nasca | G47: =ROUND(1/(1-G14/100),4) | H47: =ROUND(1/(1-H14/100),4) | I47: =ROUND(1/(1-(U14-O14-Q14-S14)/100),4) | J47: =ROUND(1/(1-(V14-P14-R14-T14)/100),4) | K47: =ROUND(1/(1-U14/100),4) | L47: =ROUND(1/(1-V14/100),4) | M47: =ROUND(1/(1-AB14/100),4) | N47: =ROUND(1/(1-AC14/100),4)
C48: 10 | D48: SE2046 | E48: ST2 | F48: Paracas | G48: =ROUND(1/(1-G15/100),4) | H48: =ROUND(1/(1-H15/100),4) | I48: =ROUND(1/(1-(U15-O15-Q15-S15)/100),4) | J48: =ROUND(1/(1-(V15-P15-R15-T15)/100),4) | K48: =ROUND(1/(1-U15/100),4) | L48: =ROUND(1/(1-V15/100),4) | M48: =ROUND(1/(1-AB15/100),4) | N48: =ROUND(1/(1-AC15/100),4)
C49: 11 | D49: SE2044 | E49: ST2 | F49: Santa_Margarita | G49: =ROUND(1/(1-G16/100),4) | H49: =ROUND(1/(1-H16/100),4) | I49: =ROUND(1/(1-(U16-O16-Q16-S16)/100),4) | J49: =ROUND(1/(1-(V16-P16-R16-T16)/100),4) | K49: =ROUND(1/(1-U16/100),4) | L49: =ROUND(1/(1-V16/100),4) | M49: =ROUND(1/(1-AB16/100),4) | N49: =ROUND(1/(1-AC16/100),4)
C50: 12 | D50: SE1043 | E50: ST2 | F50: Chincha_Baja_Densidad | G50: =ROUND(1/(1-G17/100),4) | H50: =ROUND(1/(1-H17/100),4) | I50: =ROUND(1/(1-(U17-O17-Q17-S17)/100),4) | J50: =ROUND(1/(1-(V17-P17-R17-T17)/100),4) | K50: =ROUND(1/(1-U17/100),4) | L50: =ROUND(1/(1-V17/100),4) | M50: =ROUND(1/(1-AB17/100),4) | N50: =ROUND(1/(1-AC17/100),4)
... C65: 27 | D65: SR0045 | E65: SER | F65: SER_Nasca | G65: =ROUND(1/(1-G32/100),4) | H65: =ROUND(1/(1-H32/100),4) | I65: =ROUND(1/(1-(U32-O32-Q32-S32)/100),4) | J65: =ROUND(1/(1-(V32-P32-R32-T32)/100),4) | K65: =ROUND(1/(1-U32/100),4) | L65: =ROUND(1/(1-V32/100),4) | M65: =ROUND(1/(1-AB32/100),4) | N65: =ROUND(1/(1-AC32/100),4)
C68: Cuadros para el Informe:
G71: Sector Típico 2 | H71: Sector Típico 3 | I71: Sector Típico 4 | J71: Sector Típico SER
F72: Media Tensión
F73: Energía | G73: =$G$7/100 | H73: =$G$8/100 | I73: =$G$9/100 | J73: =$G$10/100
F74: Potencia | G74: =$H$7/100 | H74: =$H$8/100 | I74: =$H$9/100 | J74: =$H$10/100
F75: Baja Tensión
F76: Energía | G76: =G77+G82 | H76: =H77+H82 | I76: =I77+I82 | J76: =J77+J82
F77: Técnicas | G77: =SUM(G78:G81) | H77: =SUM(H78:H81) | I77: =SUM(I78:I81) | J77: =SUM(J78:J81)
...

Sheet Unifilar_Trafo_Cargas_2
B2: SISTEMA ELÉCTRICO - SET PEDREGAL | AB2: SISTEMA ELÉCTRICO - SET EL CARMEN
B7: (CONFIGURACION ACTUAL SET PEDREGAL) | AB7: (CONFIGURACION ACTUAL SET EL CARMEN)
B8: EPOCAS DE ALTO CONSUMO | AB8: EPOCAS DE ALTO CONSUMO
E11: TRAFO 01 | I11: 60/10 KV | AE11: TRAFO 01 | AI11: 60/10 KV
E13: Pot. Inst. | I13: 25 | J13: 31.25 | K13: MVA ONAF | AE13: Pot. Inst. | AI13: 7 | AJ13: 8.4 | AK13: MVA ONAF
E14: Demanda | I14: =F22&" / "&L22&" MVA" | AE14: Demanda | AI14: =AF22&" / "&AL22&" MVA"
P17: PE101 | Q17: 6.655 | R17: MW | T17: 2.268 | U17: MVAR | AP17: CA101 | AQ17: 4.724 | AR17: MW | AT17: 1.052 | AU17: MVAR
P19: PE102 | Q19: 7.542 | R19: MW | T19: 2.563 | U19: MVAR | AQ19: 0 | AR19: MW | AU19: MVAR
F21: 20.728 | G21: MW | L21: 20.945 | M21: MW | P21: PE103 | Q21: 3.583 | R21: MW | T21: 0.508 | U21: MVAR | AF21: 8.6023 | AG21: MW | AL21: 8.567 | AM21: MW | AP21: CA103 | AQ21: RESERVA | AR21: MW | AT21: RESERVA | AU21: MVAR
F22: =+ROUND(SQRT(POWER(F21,2)+POWER(F23,2)),2) | G22: MVA | L22: =+ROUND(SQRT(POWER(L21,2)+POWER(L23,2)),2) | M22: MVA | AF22: =+ROUND(SQRT(POWER(AF21,2)+POWER(AF23,2)),2) | AG22: MVA | AL22: =+ROUND(SQRT(POWER(AL21,2)+POWER(AL23,2)),2) | AM22: MVA
F23: 7.481 | G23: MVAR | L23: 6.128 | M23: MVAR | P23: PE104 | Q23: 6.051 | R23: MW | T23: 2.236 | U23: MVAR | AF23: 2.2964 | AG23: MVAR | AL23: 1.142 | AM23: MVAR | AP23: CA104 | AQ23: 1.471 | AR23: MW | AT23: 0.843 | AU23: MVAR
F24: =+F22/$J$13 | G24: :FU | L24: =+L22/$J$13 | M24: :FU | AF24: =+AF22/$AJ$13 | AG24: :FU | AL24: =+AL22/$AJ$13 | AM24: :FU
P25: PE105 | Q25: 3.037 | R25: MW | T25: -0.155 | U25: MVAR | AF25: 22/10/2019 09:15:00 | AL25: 22/10/2019 09:15:00 | AP25: CA105 | AQ25: 4.679 | AR25: MW | AT25: 0.788 | AU25: MVAR
N32: F.Coinc: | O32: =+L21/(Q17+Q19+IF(Q21="RESERVA",0,)+Q23+Q25) | AN32: F.Coinc: | AO32: =+AL21/(AQ17+AQ19+IF(AQ21="RESERVA",0,)+AQ23+AQ25)
D35: RESERVA (ONAF) : | E35: TRAFO 01 | M35: TOTAL | AD35: RESERVA (ONAF) : | AE35: TRAFO 01 | AM35: TOTAL
E36: 220 kV | F36: 0 | G36: MVA | M36: 220 kV | N36: 0 | O36: MVA | AE36: 220 kV | AF36: 0 | AG36: MVA | AM36: 220 kV | AN36: 0 | AO36: MVA
E37: 60 kV | F37: =$J$13-$F$22 | G37: MVA | M37: 60 kV | N37: =+F37+J37 | O37: MVA | P37: =+IF(MID(SIGN($N$37),1,1)="-","SOBRECARGA DEL TRAFO - ROTAR TRAFO","RESERVA_TOTAL_DEL_TRANSFORMADOR_DE_POTENCIA") | AE37: 60 kV | AF37: =$AJ$13-$AF$22 | AG37: MVA | AM37: 60 kV | AN37: =+AF37+AJ37 | AO37: MVA | AP37: =+IF(MID(SIGN($AN$37),1,1)="-","SOBRECARGA DEL TRAFO - ROTAR TRAFO","RESERVA_TOTAL_DEL_TRANSFORMADOR_DE_POTENCIA")
E38: 22.9kK | F38: 0 | G38: MVA | M38: 22.9kV | N38: 0 | O38: MVA | AE38: 22.9kK | AF38: 0 | AG38: MVA | AM38: 22.9kV | AN38: 0 | AO38: MVA
E39: 10 kV | F39: =$J$13-$L$22 | G39: MVA | M39: 10 kV | N39: =+J39+F39 | O39: MVA | P39: =+IF(MID(SIGN($N$39),1,1)="-","SOBRECARGA DEL TRAFO - ROTAR TRAFO","RESERVA_TOTAL_DEL_TRANSFORMADOR_DE_POTENCIA") | AE39: 10 kV | AF39: =$AJ$13-$AL$22 | AG39: MVA | AM39: 10 kV | AN39: =+AJ39+AF39 | AO39: MVA | AP39: =+IF(MID(SIGN($AN$39),1,1)="-","SOBRECARGA DEL TRAFO - ROTAR TRAFO","RESERVA_TOTAL_DEL_TRANSFORMADOR_DE_POTENCIA")
B44: ESCENARIO 1: | AB44: ESCENARIO 1:
B49: CONFIGURACION ACTUAL - TRANFERENCIA + INCREMENTO DE POTENCIA DE 0.587MW | AB49: ROTACIÓN DE TRAFO DE LUREN DE 15MVA A EL CARMEN CON MAXIMA DEMANDA 2019 + TRANSFERENCIA DE PE101 A CA105
E52: TRAFO 01 | I52: 60/10 KV | AE52: TRAFO 01 | AI52: 60/10 KV
E54: Pot. Inst. | I54: 25 | J54: 31.25 | K54: MVA ONAF | AE54: Pot. Inst. | AI54: 15 | AJ54: 18.75 | AK54: MVA ONAF
E55: Demanda | I55: =F63&" / "&L63&" MVA" | AE55: Demanda | AI55: =AF63&" / "&AL63&" MVA"
P58: PE101 | Q58: =6.655-#REF!/1000+#REF!/1000 | R58: MW | T58: 2.268 | U58: MVAR | AP58: CA101 | AQ58: 4.724 | AR58: MW | AT58: 1.052 | AU58: MVAR
P60: PE102 | Q60: 7.542 | R60: MW | T60: 2.563 | U60: MVAR | AP60: CA102 | AQ60: 0 | AR60: MW | AT60: 0 | AU60: MVAR
F62: 20.728 | G62: MW | L62: 20.945 | M62: MW | P62: PE103 | Q62: 3.583 | R62: MW | T62: 0.508 | U62: MVAR | AF62: =8.6023+#REF!/1000 | AG62: MW | AL62: =8.567+#REF!/1000 | AM62: MW | AP62: CA103 | AQ62: RESERVA | AR62: MW | AT62: RESERVA | AU62: MVAR
F63: =+ROUND(SQRT(POWER(F62,2)+POWER(F64,2)),2) | G63: MVA | L63: =+ROUND(SQRT(POWER(L62,2)+POWER(L64,2)),2) | M63: MVA | AF63: =+ROUND(SQRT(POWER(AF62,2)+POWER(AF64,2)),2) | AG63: MVA | AL63: =+ROUND(SQRT(POWER(AL62,2)+POWER(AL64,2)),2) | AM63: MVA
F64: 7.481 | G64: MVAR | L64: 6.128 | M64: MVAR | P64: PE104 | Q64: 6.051 | R64: MW | T64: 2.236 | U64: MVAR | AF64: 2.2964 | AG64: MVAR | AL64: 1.142 | AM64: MVAR | AP64: CA104 | AQ64: 1.471 | AR64: MW | AT64: 0.843 | AU64: MVAR
F65: =+F63/$J$13 | G65: :FU | L65: =+L63/$J$13 | M65: :FU | AF65: =+AF63/$AJ$54 | AG65: :FU | AL65: =+AL63/$AJ$54 | AM65: :FU
P66: PE105 | Q66: 3.037 | R66: MW | T66: -0.155 | U66: MVAR | AP66: CA105 | AQ66: =4.679+#REF!/1000 | AR66: MW | AT66: 0.788 | AU66: MVAR
N73: F.Coinc: | O73: =+L62/(Q58+Q60+Q62+Q64+Q66) | AN73: F.Coinc: | AO73: =+AL62*1000/(AQ58+AQ60+IF(AQ62="RESERVA",0,)+AQ64+AQ66)
D76: RESERVA (ONAF) : | E76: TRAFO 01 | M76: TOTAL | AD76: RESERVA (ONAF) : | AE76: TRAFO 01 | AM76: TOTAL
E77: 220 kV | F77: =50-F63 | G77: MVA | M77: 220 kV | N77: =+F77+J77 | O77: MVA | AE77: 220 kV | AF77: 0 | AG77: MVA | AM77: 220 kV | AN77: 0 | AO77: MVA
E78: 60 kV | F78: =50-L52 | G78: MVA | M78: 60 kV | N78: =+F78+J78 | O78: MVA | AE78: 60 kV | AF78: =$AJ$54-$AF$63 | AG78: MVA | AM78: 60 kV | AN78: =+AF78+AJ78 | AO78: MVA | AP78: =+IF(MID(SIGN($AN$78),1,1)="-","SOBRECARGA DEL TRAFO - ROTAR TRAFO","RESERVA_TOTAL_DEL_TRANSFORMADOR_DE_POTENCIA")
E79: 10 kV | F79: =30-L63 | G79: MVA | M79: 10 kV | N79: =+J79+F79 | O79: MVA | P79: RESERVA TOTAL DEL TRANSFORMADOR DE POTENCIA | AE79: 22.9kK | AF79: 0 | AG79: MVA | AM79: 22.9kV | AN79: 0 | AO79: MVA
AE80: 10 kV | AF80: =$AJ$54-$AL$63 | AG80: MVA | AM80: 10 kV | AN80: =+AJ80+AF80 | AO80: MVA | AP80: =+IF(MID(SIGN($AN$80),1,1)="-","SOBRECARGA DEL TRAFO - ROTAR TRAFO","RESERVA_TOTAL_DEL_TRANSFORMADOR_DE_POTENCIA")

Sheet INVERSION_VNR_LINEA

Sheet 1) Red Actual
A2: Flujo de carga - Reporte sumario
A5: Parámetros del estudio
A7: Nombre del estudio
A8: Fecha | D8: Fri Dec 22 2017
A9: Tiempo | D9: 12h25m19s
A10: Nombre del proyecto | D10: Nuevo
A12: Método de cálculo | D12: Caída de tensión - Desequilibrada
A13: Precisión | D13: 0.1 %
A14: Factores de carga | D14: Global (P=100.00%, Q=100.00%)
A15: Factores de motor | D15: Como definido
A16: Factores de generador | D16: Como definido
A17: Condensadores shunt | D17: On
A18: Modelo de carga de sensibilidad | D18: De la biblioteca
A23: Resumen total | D23: kW | E23: kvar | F23: kVA | G23: FP(%)
A25: Fuentes (Potencia de equilibrio) | D25: 7861.728 | E25: 2845.7414 | F25: 8360.9216 | G25: 94.029442
A26: Generadores | D26: 0 | E26: 0 | F26: 0 | G26: 0
A27: Producción total | D27: 7861.728 | E27: 2845.7414 | F27: 8360.9216 | G27: 94.029442
A29: Carga leída (no regulada) | D29: 7810.8628 | E29: 4467.2111 | F29: 8998.0861 | G29: 86.805825
A30: Carga utilizada (regulada) | D30: 7809.2103 | E30: 4466.5301 | F30: 8996.3136 | G30: 86.804559
A31: Condensadores shunt (regulados) | D31: 0 | E31: -1688.3325 | F31: 1688.3325 | G31: 0
A32: Reactancias shunt(reguladas) | D32: 0 | E32: 0 | F32: 0 | G32: 0
A33: Motores | D33: 0 | E33: 0 | F33: 0 | G33: 0
A34: Cargas totales | D34: 7809.2103 | E34: 2778.1976 | F34: 8288.6759 | G34: 94.215414
A36: Capacitancia del cable | D36: 0 | E36: -5.5196289 | F36: 5.5196289 | G36: 0
A37: Capacitancia de la línea | D37: 0 | E37: -11.355375 | F37: 11.355375 | G37: 0
A38: Capacitancia shunt total | D38: 0 | E38: -16.875004 | F38: 16.875004 | G38: 0
... A44: Pérdidas totales | D44: 52.471234 | E44: 84.41883 | F44: 99.397028 | G44: 52.78954
A49: Condiciones anormales | D49: Fase | E49: Conteo | F49: Peor caso | I49: Valor
D50: A | E50: 10 | F50: SEC_1080_848857_848857 | I50: 111.50 %
A51: Sobrecarga | D51: B | E51: 10 | F51: SEC_1080_848857_848857 | I51: 111.50 %
D52: C | E52: 10 | F52: SEC_1080_848857_848857 | I52: 111.50 %
D53: A | E53: 0 | F53: NODE_2010_326877_SE30738_VIRTUAL | I53: 100.63 %
A54: Subtensión | D54: B | E54: 0 | F54: NODE_2010_326877_SE30738_VIRTUAL | I54: 100.63 %
D55: C | E55: 0 | F55: NODE_2010_326877_SE30738_VIRTUAL | I55: 100.63 %
D56: A | E56: 0 | F56: NET_2030_154_PA108 | I56: 102.00 %
A57: Sobretensión | D57: B | E57: 0 | F57: NET_2030_154_PA108 | I57: 102.00 %
D58: C | E58: 0 | F58: NET_2030_154_PA108 | I58: 102.00 %
A62: Costo anual de las pérdidas del sistema | D62: kW | E62: MW-h/año | F62: k$/año
A64: Pérdidas en las líneas | D64: 49.497343 | E64: 433.59672 | F64: 43.359672
A65: Pérdidas en los cables | D65: 2.9738907 | E65: 26.051283 | F65: 2.6051283
...

Sheet 2) Ingreso SU
A2: Flujo de carga - Reporte sumario
A5: Parámetros del estudio
A7: Nombre del estudio
A8: Fecha | D8: Fri Dec 22 2017
A9: Tiempo | D9: 12h39m51s
A10: Nombre del proyecto | D10: Nuevo
A12: Método de cálculo | D12: Caída de tensión - Desequilibrada
A13: Precisión | D13: 0.1 %
A14: Factores de carga | D14: Global (P=100.00%, Q=100.00%)
A15: Factores de motor | D15: Como definido
A16: Factores de generador | D16: Como definido
A17: Condensadores shunt | D17: On
A18: Modelo de carga de sensibilidad | D18: De la biblioteca
A23: Resumen total | D23: kW | E23: kvar | F23: kVA | G23: FP(%)
A25: Fuentes (Potencia de equilibrio) | D25: 8572.1727 | E25: 3096.5652 | F25: 9114.3218 | G25: 94.05168
A26: Generadores | D26: 0 | E26: 0 | F26: 0 | G26: 0
A27: Producción total | D27: 8572.1727 | E27: 3096.5652 | F27: 9114.3218 | G27: 94.05168
A29: Carga leída (no regulada) | D29: 8510.8628 | E29: 4697.29 | F29: 9721.0761 | G29: 87.550625
A30: Carga utilizada (regulada) | D30: 8508.6169 | E30: 4696.401 | F30: 9718.6801 | G30: 87.549099
A31: Condensadores shunt (regulados) | D31: 0 | E31: -1685.2108 | F31: 1685.2108 | G31: 0
A32: Reactancias shunt(reguladas) | D32: 0 | E32: 0 | F32: 0 | G32: 0
A33: Motores | D33: 0 | E33: 0 | F33: 0 | G33: 0
A34: Cargas totales | D34: 8508.6169 | E34: 3011.1902 | F34: 9025.7314 | G34: 94.270663
A36: Capacitancia del cable | D36: 0 | E36: -5.5137477 | F36: 5.5137477 | G36: 0
A37: Capacitancia de la línea | D37: 0 | E37: -11.393771 | F37: 11.393771 | G37: 0
A38: Capacitancia shunt total | D38: 0 | E38: -16.907519 | F38: 16.907519 | G38: 0
... A44: Pérdidas totales | D44: 63.503932 | E44: 102.28255 | F44: 120.39298 | G44: 52.747206
A49: Condiciones anormales | D49: Fase | E49: Conteo | F49: Peor caso | I49: Valor
D50: A | E50: 10 | F50: SEC_1080_848857_848857 | I50: 111.83 %
A51: Sobrecarga | D51: B | E51: 10 | F51: SEC_1080_848857_848857 | I51: 111.83 %
D52: C | E52: 10 | F52: SEC_1080_848857_848857 | I52: 111.83 %
D53: A | E53: 0 | F53: NODE_2010_326877_SE30738_VIRTUAL | I53: 100.36 %
A54: Subtensión | D54: B | E54: 0 | F54: NODE_2010_326877_SE30738_VIRTUAL | I54: 100.36 %
D55: C | E55: 0 | F55: NODE_2010_326877_SE30738_VIRTUAL | I55: 100.36 %
D56: A | E56: 0 | F56: NET_2030_154_PA108 | I56: 102.00 %
A57: Sobretensión | D57: B | E57: 0 | F57: NET_2030_154_PA108 | I57: 102.00 %
D58: C | E58: 0 | F58: NET_2030_154_PA108 | I58: 102.00 %
A62: Costo anual de las pérdidas del sistema | D62: kW | E62: MW-h/año | F62: k$/año
A64: Pérdidas en las líneas | D64: 60.005738 | E64: 525.65026 | F64: 52.565026
A65: Pérdidas en los cables | D65: 3.498194 | E65: 30.64418 | F65: 3.064418
...
